[2021-06-04 19:08:15,903] [9888]] [13672] [        views.py:  30] [INFO  ] 添加用户成功.
[2021-06-05 11:56:26,883] [12064]] [13728] [        views.py: 253] [ERROR ] 添加用户失败Traceback (most recent call last):
  File "E:\01 Network\07 Program\python\django3.1\mysite\users\views.py", line 249, in post
    userform.save()
AttributeError: 'UserForm' object has no attribute 'save'

[2021-06-05 11:57:19,995] [11016]] [18764] [        views.py: 253] [ERROR ] 添加用户失败Traceback (most recent call last):
  File "E:\01 Network\07 Program\python\django3.1\mysite\users\views.py", line 249, in post
    userform.save()
AttributeError: 'UserForm' object has no attribute 'save'

[2021-06-05 11:57:51,952] [11016]] [18764] [        views.py: 253] [ERROR ] 添加用户失败Traceback (most recent call last):
  File "E:\01 Network\07 Program\python\django3.1\mysite\users\views.py", line 249, in post
    userform.save()
AttributeError: 'UserForm' object has no attribute 'save'

[2021-06-05 11:58:24,094] [11016]] [18764] [        views.py: 253] [ERROR ] 添加用户失败Traceback (most recent call last):
  File "E:\01 Network\07 Program\python\django3.1\mysite\users\views.py", line 249, in post
    userform.save()
AttributeError: 'UserForm' object has no attribute 'save'

[2021-06-05 11:58:45,727] [11016]] [18764] [        views.py: 253] [ERROR ] 添加用户失败Traceback (most recent call last):
  File "E:\01 Network\07 Program\python\django3.1\mysite\users\views.py", line 249, in post
    userform.save()
AttributeError: 'UserForm' object has no attribute 'save'

[2021-06-05 11:58:49,763] [11016]] [18764] [        views.py: 253] [ERROR ] 添加用户失败Traceback (most recent call last):
  File "E:\01 Network\07 Program\python\django3.1\mysite\users\views.py", line 249, in post
    userform.save()
AttributeError: 'UserForm' object has no attribute 'save'

[2021-06-05 11:59:43,980] [15884]] [16472] [        views.py: 253] [ERROR ] 添加用户失败Traceback (most recent call last):
  File "E:\01 Network\07 Program\python\django3.1\mysite\users\views.py", line 249, in post
    userform.save()
AttributeError: 'UserForm' object has no attribute 'save'

[2021-06-05 12:11:03,046] [616]] [14376] [        views.py: 267] [ERROR ] 添加用户失败Traceback (most recent call last):
  File "E:\01 Network\07 Program\python\django3.1\mysite\users\views.py", line 261, in post
    self.model.objects.get_or_create(data)
  File "E:\01 Network\07 Program\python\django3.1\mysite\venv\lib\site-packages\django\db\models\manager.py", line 85, in manager_method
    return getattr(self.get_queryset(), name)(*args, **kwargs)
  File "E:\01 Network\07 Program\python\django3.1\mysite\venv\lib\site-packages\django\db\models\query.py", line 581, in get_or_create
    return self.get(**kwargs), False
  File "E:\01 Network\07 Program\python\django3.1\mysite\venv\lib\site-packages\django\db\models\query.py", line 442, in get
    num if not limit or num < limit else 'more than %s' % (limit - 1),
users.models.User.MultipleObjectsReturned: get() returned more than one User -- it returned 2!

[2021-06-05 12:11:13,856] [616]] [14376] [        views.py: 267] [ERROR ] 添加用户失败Traceback (most recent call last):
  File "E:\01 Network\07 Program\python\django3.1\mysite\users\views.py", line 261, in post
    self.model.objects.get_or_create(data)
  File "E:\01 Network\07 Program\python\django3.1\mysite\venv\lib\site-packages\django\db\models\manager.py", line 85, in manager_method
    return getattr(self.get_queryset(), name)(*args, **kwargs)
  File "E:\01 Network\07 Program\python\django3.1\mysite\venv\lib\site-packages\django\db\models\query.py", line 581, in get_or_create
    return self.get(**kwargs), False
  File "E:\01 Network\07 Program\python\django3.1\mysite\venv\lib\site-packages\django\db\models\query.py", line 442, in get
    num if not limit or num < limit else 'more than %s' % (limit - 1),
users.models.User.MultipleObjectsReturned: get() returned more than one User -- it returned 2!

[2021-06-05 12:11:20,170] [616]] [14376] [        views.py: 271] [ERROR ] 添加用户失败NoneType: None

[2021-06-05 12:11:57,070] [14744]] [10868] [        views.py: 267] [ERROR ] 添加用户失败Traceback (most recent call last):
  File "E:\01 Network\07 Program\python\django3.1\mysite\users\views.py", line 261, in post
    self.model.objects.create(data)
  File "E:\01 Network\07 Program\python\django3.1\mysite\venv\lib\site-packages\django\db\models\manager.py", line 85, in manager_method
    return getattr(self.get_queryset(), name)(*args, **kwargs)
TypeError: create() takes 1 positional argument but 2 were given

[2021-06-05 12:15:27,058] [16136]] [16656] [        views.py: 267] [ERROR ] 添加用户失败Traceback (most recent call last):
  File "E:\01 Network\07 Program\python\django3.1\mysite\users\views.py", line 261, in post
    self.model.objects.create(data)
  File "E:\01 Network\07 Program\python\django3.1\mysite\venv\lib\site-packages\django\db\models\manager.py", line 85, in manager_method
    return getattr(self.get_queryset(), name)(*args, **kwargs)
TypeError: create() takes 1 positional argument but 2 were given

[2021-06-05 12:16:12,523] [9764]] [9204] [        views.py: 268] [ERROR ] 添加用户失败Traceback (most recent call last):
  File "E:\01 Network\07 Program\python\django3.1\mysite\users\views.py", line 261, in post
    self.model.objects.create(data)
  File "E:\01 Network\07 Program\python\django3.1\mysite\venv\lib\site-packages\django\db\models\manager.py", line 85, in manager_method
    return getattr(self.get_queryset(), name)(*args, **kwargs)
TypeError: create() takes 1 positional argument but 2 were given

[2021-06-05 12:17:05,741] [14196]] [11844] [        views.py: 266] [ERROR ] 添加用户失败Traceback (most recent call last):
  File "E:\01 Network\07 Program\python\django3.1\mysite\users\views.py", line 261, in post
    self.model.objects.create(data)
AttributeError: type object 'UserModelForm' has no attribute 'objects'

[2021-06-05 12:17:56,342] [8928]] [15700] [        views.py: 266] [ERROR ] 添加用户失败Traceback (most recent call last):
  File "E:\01 Network\07 Program\python\django3.1\mysite\users\views.py", line 261, in post
    self.model.objects.create(data)
  File "E:\01 Network\07 Program\python\django3.1\mysite\venv\lib\site-packages\django\db\models\manager.py", line 85, in manager_method
    return getattr(self.get_queryset(), name)(*args, **kwargs)
TypeError: create() takes 1 positional argument but 2 were given

[2021-06-05 12:18:29,914] [8928]] [15700] [        views.py: 266] [ERROR ] 添加用户失败Traceback (most recent call last):
  File "E:\01 Network\07 Program\python\django3.1\mysite\users\views.py", line 261, in post
    self.model.objects.create(data)
  File "E:\01 Network\07 Program\python\django3.1\mysite\venv\lib\site-packages\django\db\models\manager.py", line 85, in manager_method
    return getattr(self.get_queryset(), name)(*args, **kwargs)
TypeError: create() takes 1 positional argument but 2 were given

[2021-06-06 10:50:40,107] [17288]] [14136] [        views.py: 277] [ERROR ] 添加用户失败Traceback (most recent call last):
  File "E:\01 Network\07 Program\python\django3.1\mysite\users\views.py", line 271, in post
    self.model.objects.create(data)
  File "E:\01 Network\07 Program\python\django3.1\mysite\venv\lib\site-packages\django\db\models\manager.py", line 85, in manager_method
    return getattr(self.get_queryset(), name)(*args, **kwargs)
TypeError: create() takes 1 positional argument but 2 were given

[2021-06-06 14:13:33,772] [7696]] [20292] [        views.py: 337] [ERROR ] delete user error：Traceback (most recent call last):
  File "E:\01 Network\07 Program\python\django3.1\mysite\venv\lib\site-packages\django\db\models\fields\__init__.py", line 1823, in get_prep_value
    return int(value)
TypeError: int() argument must be a string, a bytes-like object or a number, not 'dict'

The above exception was the direct cause of the following exception:

Traceback (most recent call last):
  File "E:\01 Network\07 Program\python\django3.1\mysite\users\views.py", line 330, in delete
    self.model.objects.filter(id=kwargs).delete()
  File "E:\01 Network\07 Program\python\django3.1\mysite\venv\lib\site-packages\django\db\models\manager.py", line 85, in manager_method
    return getattr(self.get_queryset(), name)(*args, **kwargs)
  File "E:\01 Network\07 Program\python\django3.1\mysite\venv\lib\site-packages\django\db\models\query.py", line 941, in filter
    return self._filter_or_exclude(False, args, kwargs)
  File "E:\01 Network\07 Program\python\django3.1\mysite\venv\lib\site-packages\django\db\models\query.py", line 961, in _filter_or_exclude
    clone._filter_or_exclude_inplace(negate, args, kwargs)
  File "E:\01 Network\07 Program\python\django3.1\mysite\venv\lib\site-packages\django\db\models\query.py", line 968, in _filter_or_exclude_inplace
    self._query.add_q(Q(*args, **kwargs))
  File "E:\01 Network\07 Program\python\django3.1\mysite\venv\lib\site-packages\django\db\models\sql\query.py", line 1396, in add_q
    clause, _ = self._add_q(q_object, self.used_aliases)
  File "E:\01 Network\07 Program\python\django3.1\mysite\venv\lib\site-packages\django\db\models\sql\query.py", line 1418, in _add_q
    split_subq=split_subq, check_filterable=check_filterable,
  File "E:\01 Network\07 Program\python\django3.1\mysite\venv\lib\site-packages\django\db\models\sql\query.py", line 1350, in build_filter
    condition = self.build_lookup(lookups, col, value)
  File "E:\01 Network\07 Program\python\django3.1\mysite\venv\lib\site-packages\django\db\models\sql\query.py", line 1196, in build_lookup
    lookup = lookup_class(lhs, rhs)
  File "E:\01 Network\07 Program\python\django3.1\mysite\venv\lib\site-packages\django\db\models\lookups.py", line 25, in __init__
    self.rhs = self.get_prep_lookup()
  File "E:\01 Network\07 Program\python\django3.1\mysite\venv\lib\site-packages\django\db\models\lookups.py", line 77, in get_prep_lookup
    return self.lhs.output_field.get_prep_value(self.rhs)
  File "E:\01 Network\07 Program\python\django3.1\mysite\venv\lib\site-packages\django\db\models\fields\__init__.py", line 1827, in get_prep_value
    ) from e
TypeError: Field 'id' expected a number but got {'pk': '6'}.

[2021-06-14 12:56:09,445] [13704]] [2256] [        views.py: 492] [ERROR ] delete user error：Traceback (most recent call last):
  File "E:\01 Network\07 Program\python\django3.1\mysite\venv\lib\site-packages\django\views\generic\detail.py", line 52, in get_object
    obj = queryset.get()
  File "E:\01 Network\07 Program\python\django3.1\mysite\venv\lib\site-packages\django\db\models\query.py", line 437, in get
    self.model._meta.object_name
users.models.User.DoesNotExist: User matching query does not exist.

During handling of the above exception, another exception occurred:

Traceback (most recent call last):
  File "E:\01 Network\07 Program\python\django3.1\mysite\users\views.py", line 488, in delete
    self.get_object().delete()
  File "E:\01 Network\07 Program\python\django3.1\mysite\venv\lib\site-packages\django\views\generic\detail.py", line 55, in get_object
    {'verbose_name': queryset.model._meta.verbose_name})
django.http.response.Http404: 没有找到符合查询的 user

[2021-06-14 12:56:40,805] [13704]] [2256] [        views.py: 492] [ERROR ] delete user error：Traceback (most recent call last):
  File "E:\01 Network\07 Program\python\django3.1\mysite\venv\lib\site-packages\django\views\generic\detail.py", line 52, in get_object
    obj = queryset.get()
  File "E:\01 Network\07 Program\python\django3.1\mysite\venv\lib\site-packages\django\db\models\query.py", line 437, in get
    self.model._meta.object_name
users.models.User.DoesNotExist: User matching query does not exist.

During handling of the above exception, another exception occurred:

Traceback (most recent call last):
  File "E:\01 Network\07 Program\python\django3.1\mysite\users\views.py", line 488, in delete
    self.get_object().delete()
  File "E:\01 Network\07 Program\python\django3.1\mysite\venv\lib\site-packages\django\views\generic\detail.py", line 55, in get_object
    {'verbose_name': queryset.model._meta.verbose_name})
django.http.response.Http404: 没有找到符合查询的 user

[2021-06-14 12:58:27,467] [13704]] [2256] [        views.py: 492] [ERROR ] delete user error：Traceback (most recent call last):
  File "E:\01 Network\07 Program\python\django3.1\mysite\venv\lib\site-packages\django\views\generic\detail.py", line 52, in get_object
    obj = queryset.get()
  File "E:\01 Network\07 Program\python\django3.1\mysite\venv\lib\site-packages\django\db\models\query.py", line 437, in get
    self.model._meta.object_name
users.models.User.DoesNotExist: User matching query does not exist.

During handling of the above exception, another exception occurred:

Traceback (most recent call last):
  File "E:\01 Network\07 Program\python\django3.1\mysite\users\views.py", line 488, in delete
    self.get_object().delete()
  File "E:\01 Network\07 Program\python\django3.1\mysite\venv\lib\site-packages\django\views\generic\detail.py", line 55, in get_object
    {'verbose_name': queryset.model._meta.verbose_name})
django.http.response.Http404: 没有找到符合查询的 user

[2021-06-14 12:59:53,052] [13704]] [2256] [        views.py: 492] [ERROR ] delete user error：Traceback (most recent call last):
  File "E:\01 Network\07 Program\python\django3.1\mysite\venv\lib\site-packages\django\views\generic\detail.py", line 52, in get_object
    obj = queryset.get()
  File "E:\01 Network\07 Program\python\django3.1\mysite\venv\lib\site-packages\django\db\models\query.py", line 437, in get
    self.model._meta.object_name
users.models.User.DoesNotExist: User matching query does not exist.

During handling of the above exception, another exception occurred:

Traceback (most recent call last):
  File "E:\01 Network\07 Program\python\django3.1\mysite\users\views.py", line 488, in delete
    self.get_object().delete()
  File "E:\01 Network\07 Program\python\django3.1\mysite\venv\lib\site-packages\django\views\generic\detail.py", line 55, in get_object
    {'verbose_name': queryset.model._meta.verbose_name})
django.http.response.Http404: 没有找到符合查询的 user

